<?xml version="1.0" encoding="UTF-8"?>
<!-- Generated by org.testng.reporters.JUnitReportReporter -->
<testsuite hostname="Dell" failures="0" tests="4" name="com.XooperAPIFlows.AIJDCreation_APIFlow" time="3.053" errors="1" timestamp="2025-03-17T16:01:08 IST" skipped="0">
  <testcase classname="com.XooperAPIFlows.AIJDCreation_APIFlow" name="AIJDwithExcelTestData" time="2.560"/>
  <system-out/>
  <testcase classname="com.XooperAPIFlows.AIJDCreation_APIFlow" name="AIJDwithInvalidExcelTestData" time="0.160">
    <error message="
Expected exception of type class java.lang.RuntimeException but got java.lang.AssertionError: API returned 422 Unprocessable Entity as expected." type="org.testng.TestException">
      <![CDATA[org.testng.TestException: 
Expected exception of type class java.lang.RuntimeException but got java.lang.AssertionError: API returned 422 Unprocessable Entity as expected.
at org.testng.internal.ExpectedExceptionsHolder.wrongException(ExpectedExceptionsHolder.java:68)
at org.testng.internal.TestInvoker.considerExceptions(TestInvoker.java:739)
at org.testng.internal.TestInvoker.invokeMethod(TestInvoker.java:634)
at org.testng.internal.TestInvoker.invokeTestMethod(TestInvoker.java:173)
at org.testng.internal.MethodRunner.runInSequence(MethodRunner.java:46)
at org.testng.internal.TestInvoker$MethodInvocationAgent.invoke(TestInvoker.java:824)
at org.testng.internal.TestInvoker.invokeTestMethods(TestInvoker.java:146)
at org.testng.internal.TestMethodWorker.invokeTestMethods(TestMethodWorker.java:146)
at org.testng.internal.TestMethodWorker.run(TestMethodWorker.java:128)
at java.base/java.util.ArrayList.forEach(ArrayList.java:1597)
at org.testng.TestRunner.privateRun(TestRunner.java:794)
at org.testng.TestRunner.run(TestRunner.java:596)
at org.testng.SuiteRunner.runTest(SuiteRunner.java:377)
at org.testng.SuiteRunner.runSequentially(SuiteRunner.java:371)
at org.testng.SuiteRunner.privateRun(SuiteRunner.java:332)
at org.testng.SuiteRunner.run(SuiteRunner.java:276)
at org.testng.SuiteRunnerWorker.runSuite(SuiteRunnerWorker.java:53)
at org.testng.SuiteRunnerWorker.run(SuiteRunnerWorker.java:96)
at org.testng.TestNG.runSuitesSequentially(TestNG.java:1212)
at org.testng.TestNG.runSuitesLocally(TestNG.java:1134)
at org.testng.TestNG.runSuites(TestNG.java:1063)
at org.testng.TestNG.run(TestNG.java:1031)
at org.testng.remote.AbstractRemoteTestNG.run(AbstractRemoteTestNG.java:115)
at org.testng.remote.RemoteTestNG.initAndRun(RemoteTestNG.java:293)
at org.testng.remote.RemoteTestNG.main(RemoteTestNG.java:91)
Caused by: java.lang.AssertionError: API returned 422 Unprocessable Entity as expected.
at com.XooperAPITest.API_AIJDCreationTest.testAIJDAPI(API_AIJDCreationTest.java:78)
at com.XooperAPIFlows.AIJDCreation_APIFlow.AIJDwithInvalidExcelTestData(AIJDCreation_APIFlow.java:54)
at java.base/jdk.internal.reflect.DirectMethodHandleAccessor.invoke(DirectMethodHandleAccessor.java:103)
at java.base/java.lang.reflect.Method.invoke(Method.java:580)
at org.testng.internal.MethodInvocationHelper.invokeMethod(MethodInvocationHelper.java:133)
at org.testng.internal.InvokeMethodRunnable.runOne(InvokeMethodRunnable.java:45)
at org.testng.internal.InvokeMethodRunnable.call(InvokeMethodRunnable.java:73)
at org.testng.internal.InvokeMethodRunnable.call(InvokeMethodRunnable.java:11)
at java.base/java.util.concurrent.FutureTask.run(FutureTask.java:317)
at java.base/java.util.concurrent.ThreadPoolExecutor.runWorker(ThreadPoolExecutor.java:1144)
at java.base/java.util.concurrent.ThreadPoolExecutor$Worker.run(ThreadPoolExecutor.java:642)
at java.base/java.lang.Thread.run(Thread.java:1575)
]]>
    </error>
  </testcase> <!-- AIJDwithInvalidExcelTestData -->
  <system-out/>
  <testcase classname="com.XooperAPIFlows.AIJDCreation_APIFlow" name="AIJDwithExcelTestData" time="0.182"/>
  <system-out/>
  <testcase classname="com.XooperAPIFlows.AIJDCreation_APIFlow" name="AIJDwithExcelTestData" time="0.151"/>
  <system-out/>
</testsuite> <!-- com.XooperAPIFlows.AIJDCreation_APIFlow -->
